  catch (const std::exception &e)
    {
	cerr << "ERROR -- caught exception: " << e.wha