tch (const std::exception &e)
    {
	cerr << "ERROR -- caught exception: " << e.what() << endl;
	assert (f